Microsoft Windows [Version 10.0.22000.978]
(c) Microsoft Corporation. All rights reserved.

C:\Users\HP\Documents\Axsos_academy\Django\django_intro\Dojoservey>call "C:\Users\HP\Documents\Axsos_academy\Django\djangoPy3Env\Scripts\activate"
(djangoPy3Env) C:\Users\HP\Documents\Axsos_academy\Django\django_intro\Dojoservey>python manage.py runserver
Watching for file changes with StatReloader
Performing system checks...

System check identified no issues (0 silenced).

You have 17 unapplied migration(s). Your project may not work properly until you apply the migrations for app(s): admin, auth, contenttypes, sessions.
Run 'python manage.py migrate' to apply them.
September 22, 2022 - 10:44:15
Django version 2.2.4, using settings 'Dojoservey.settings'
Starting development server at http://127.0.0.1:8000/
Quit the server with CTRL-BREAK.

(djangoPy3Env) C:\Users\HP\Documents\Axsos_academy\Django\django_intro\Dojoservey>code .

(djangoPy3Env) C:\Users\HP\Documents\Axsos_academy\Django\django_intro\Dojoservey>python manage.py runserver
Watching for file changes with StatReloader
Performing system checks...

System check identified no issues (0 silenced).

You have 17 unapplied migration(s). Your project may not work properly until you apply the migrations for app(s): admin, auth, contenttypes, sessions.
Run 'python manage.py migrate' to apply them.
September 22, 2022 - 10:44:41
Django version 2.2.4, using settings 'Dojoservey.settings'
Starting development server at http://127.0.0.1:8000/
Quit the server with CTRL-BREAK.
[22/Sep/2022 10:44:47] "GET / HTTP/1.1" 200 1142
[22/Sep/2022 10:44:51] "POST /result/ HTTP/1.1" 200 675
C:\Users\HP\Documents\Axsos_academy\Django\django_intro\Dojoservey\dojo_servey\models.py changed, reloading.
Watching for file changes with StatReloader
Performing system checks...

System check identified no issues (0 silenced).

You have 17 unapplied migration(s). Your project may not work properly until you apply the migrations for app(s): admin, auth, contenttypes, sessions.
Run 'python manage.py migrate' to apply them.
September 22, 2022 - 10:50:44
Django version 2.2.4, using settings 'Dojoservey.settings'
Starting development server at http://127.0.0.1:8000/
Quit the server with CTRL-BREAK.
C:\Users\HP\Documents\Axsos_academy\Django\django_intro\Dojoservey\dojo_servey\models.py changed, reloading.
Watching for file changes with StatReloader
Exception in thread django-main-thread:
Traceback (most recent call last):
  File "C:\Users\HP\AppData\Local\Programs\Python\Python36-32\lib\threading.py", line 916, in _bootstrap_inner
    self.run()
  File "C:\Users\HP\AppData\Local\Programs\Python\Python36-32\lib\threading.py", line 864, in run
    self._target(*self._args, **self._kwargs)
  File "C:\Users\HP\Documents\Axsos_academy\Django\djangoPy3Env\lib\site-packages\django\utils\autoreload.py", line 54, in wrapper
    fn(*args, **kwargs)
  File "C:\Users\HP\Documents\Axsos_academy\Django\djangoPy3Env\lib\site-packages\django\core\management\commands\runserver.py", line 109, in inner_run
    autoreload.raise_last_exception()
  File "C:\Users\HP\Documents\Axsos_academy\Django\djangoPy3Env\lib\site-packages\django\utils\autoreload.py", line 77, in raise_last_exception
    raise _exception[1]
  File "C:\Users\HP\Documents\Axsos_academy\Django\djangoPy3Env\lib\site-packages\django\core\management\__init__.py", line 337, in execute
    autoreload.check_errors(django.setup)()
  File "C:\Users\HP\Documents\Axsos_academy\Django\djangoPy3Env\lib\site-packages\django\utils\autoreload.py", line 54, in wrapper
    fn(*args, **kwargs)
  File "C:\Users\HP\Documents\Axsos_academy\Django\djangoPy3Env\lib\site-packages\django\__init__.py", line 24, in setup
    apps.populate(settings.INSTALLED_APPS)
  File "C:\Users\HP\Documents\Axsos_academy\Django\djangoPy3Env\lib\site-packages\django\apps\registry.py", line 114, in populate
    app_config.import_models()
  File "C:\Users\HP\Documents\Axsos_academy\Django\djangoPy3Env\lib\site-packages\django\apps\config.py", line 211, in import_models
    self.models_module = import_module(models_module_name)
  File "C:\Users\HP\AppData\Local\Programs\Python\Python36-32\lib\importlib\__init__.py", line 126, in import_module
    return _bootstrap._gcd_import(name[level:], package, level)
  File "<frozen importlib._bootstrap>", line 994, in _gcd_import
  File "<frozen importlib._bootstrap>", line 971, in _find_and_load
  File "<frozen importlib._bootstrap>", line 955, in _find_and_load_unlocked
  File "<frozen importlib._bootstrap>", line 665, in _load_unlocked
  File "<frozen importlib._bootstrap_external>", line 674, in exec_module
  File "<frozen importlib._bootstrap_external>", line 781, in get_code
  File "<frozen importlib._bootstrap_external>", line 741, in source_to_code
  File "<frozen importlib._bootstrap>", line 219, in _call_with_frames_removed
  File "C:\Users\HP\Documents\Axsos_academy\Django\django_intro\Dojoservey\dojo_servey\models.py", line 6
    def
       ^
SyntaxError: invalid syntax

C:\Users\HP\Documents\Axsos_academy\Django\django_intro\Dojoservey\dojo_servey\models.py changed, reloading.
Watching for file changes with StatReloader
Exception in thread django-main-thread:
Traceback (most recent call last):
  File "C:\Users\HP\AppData\Local\Programs\Python\Python36-32\lib\threading.py", line 916, in _bootstrap_inner
    self.run()
  File "C:\Users\HP\AppData\Local\Programs\Python\Python36-32\lib\threading.py", line 864, in run
    self._target(*self._args, **self._kwargs)
  File "C:\Users\HP\Documents\Axsos_academy\Django\djangoPy3Env\lib\site-packages\django\utils\autoreload.py", line 54, in wrapper
    fn(*args, **kwargs)
  File "C:\Users\HP\Documents\Axsos_academy\Django\djangoPy3Env\lib\site-packages\django\core\management\commands\runserver.py", line 109, in inner_run
    autoreload.raise_last_exception()
  File "C:\Users\HP\Documents\Axsos_academy\Django\djangoPy3Env\lib\site-packages\django\utils\autoreload.py", line 77, in raise_last_exception
    raise _exception[1]
  File "C:\Users\HP\Documents\Axsos_academy\Django\djangoPy3Env\lib\site-packages\django\core\management\__init__.py", line 337, in execute
    autoreload.check_errors(django.setup)()
  File "C:\Users\HP\Documents\Axsos_academy\Django\djangoPy3Env\lib\site-packages\django\utils\autoreload.py", line 54, in wrapper
    fn(*args, **kwargs)
  File "C:\Users\HP\Documents\Axsos_academy\Django\djangoPy3Env\lib\site-packages\django\__init__.py", line 24, in setup
    apps.populate(settings.INSTALLED_APPS)
  File "C:\Users\HP\Documents\Axsos_academy\Django\djangoPy3Env\lib\site-packages\django\apps\registry.py", line 114, in populate
    app_config.import_models()
  File "C:\Users\HP\Documents\Axsos_academy\Django\djangoPy3Env\lib\site-packages\django\apps\config.py", line 211, in import_models
    self.models_module = import_module(models_module_name)
  File "C:\Users\HP\AppData\Local\Programs\Python\Python36-32\lib\importlib\__init__.py", line 126, in import_module
    return _bootstrap._gcd_import(name[level:], package, level)
  File "<frozen importlib._bootstrap>", line 994, in _gcd_import
  File "<frozen importlib._bootstrap>", line 971, in _find_and_load
  File "<frozen importlib._bootstrap>", line 955, in _find_and_load_unlocked
  File "<frozen importlib._bootstrap>", line 665, in _load_unlocked
  File "<frozen importlib._bootstrap_external>", line 674, in exec_module
  File "<frozen importlib._bootstrap_external>", line 781, in get_code
  File "<frozen importlib._bootstrap_external>", line 741, in source_to_code
  File "<frozen importlib._bootstrap>", line 219, in _call_with_frames_removed
  File "C:\Users\HP\Documents\Axsos_academy\Django\django_intro\Dojoservey\dojo_servey\models.py", line 10
    description = models.TextField()
              ^
SyntaxError: invalid character in identifier

C:\Users\HP\Documents\Axsos_academy\Django\django_intro\Dojoservey\dojo_servey\models.py changed, reloading.
Watching for file changes with StatReloader
Exception in thread django-main-thread:
Traceback (most recent call last):
  File "C:\Users\HP\AppData\Local\Programs\Python\Python36-32\lib\threading.py", line 916, in _bootstrap_inner
    self.run()
  File "C:\Users\HP\AppData\Local\Programs\Python\Python36-32\lib\threading.py", line 864, in run
    self._target(*self._args, **self._kwargs)
  File "C:\Users\HP\Documents\Axsos_academy\Django\djangoPy3Env\lib\site-packages\django\utils\autoreload.py", line 54, in wrapper
    fn(*args, **kwargs)
  File "C:\Users\HP\Documents\Axsos_academy\Django\djangoPy3Env\lib\site-packages\django\core\management\commands\runserver.py", line 109, in inner_run
    autoreload.raise_last_exception()
  File "C:\Users\HP\Documents\Axsos_academy\Django\djangoPy3Env\lib\site-packages\django\utils\autoreload.py", line 77, in raise_last_exception
    raise _exception[1]
  File "C:\Users\HP\Documents\Axsos_academy\Django\djangoPy3Env\lib\site-packages\django\core\management\__init__.py", line 337, in execute
    autoreload.check_errors(django.setup)()
  File "C:\Users\HP\Documents\Axsos_academy\Django\djangoPy3Env\lib\site-packages\django\utils\autoreload.py", line 54, in wrapper
    fn(*args, **kwargs)
  File "C:\Users\HP\Documents\Axsos_academy\Django\djangoPy3Env\lib\site-packages\django\__init__.py", line 24, in setup
    apps.populate(settings.INSTALLED_APPS)
  File "C:\Users\HP\Documents\Axsos_academy\Django\djangoPy3Env\lib\site-packages\django\apps\registry.py", line 114, in populate
    app_config.import_models()
  File "C:\Users\HP\Documents\Axsos_academy\Django\djangoPy3Env\lib\site-packages\django\apps\config.py", line 211, in import_models
    self.models_module = import_module(models_module_name)
  File "C:\Users\HP\AppData\Local\Programs\Python\Python36-32\lib\importlib\__init__.py", line 126, in import_module
    return _bootstrap._gcd_import(name[level:], package, level)
  File "<frozen importlib._bootstrap>", line 994, in _gcd_import
  File "<frozen importlib._bootstrap>", line 971, in _find_and_load
  File "<frozen importlib._bootstrap>", line 955, in _find_and_load_unlocked
  File "<frozen importlib._bootstrap>", line 665, in _load_unlocked
  File "<frozen importlib._bootstrap_external>", line 674, in exec_module
  File "<frozen importlib._bootstrap_external>", line 781, in get_code
  File "<frozen importlib._bootstrap_external>", line 741, in source_to_code
  File "<frozen importlib._bootstrap>", line 219, in _call_with_frames_removed
  File "C:\Users\HP\Documents\Axsos_academy\Django\django_intro\Dojoservey\dojo_servey\models.py", line 10
    description = models.TextField()
              ^
SyntaxError: invalid character in identifier

C:\Users\HP\Documents\Axsos_academy\Django\django_intro\Dojoservey\dojo_servey\models.py changed, reloading.
Watching for file changes with StatReloader
Exception in thread django-main-thread:
Traceback (most recent call last):
  File "C:\Users\HP\AppData\Local\Programs\Python\Python36-32\lib\threading.py", line 916, in _bootstrap_inner
    self.run()
  File "C:\Users\HP\AppData\Local\Programs\Python\Python36-32\lib\threading.py", line 864, in run
    self._target(*self._args, **self._kwargs)
  File "C:\Users\HP\Documents\Axsos_academy\Django\djangoPy3Env\lib\site-packages\django\utils\autoreload.py", line 54, in wrapper
    fn(*args, **kwargs)
  File "C:\Users\HP\Documents\Axsos_academy\Django\djangoPy3Env\lib\site-packages\django\core\management\commands\runserver.py", line 109, in inner_run
    autoreload.raise_last_exception()
  File "C:\Users\HP\Documents\Axsos_academy\Django\djangoPy3Env\lib\site-packages\django\utils\autoreload.py", line 77, in raise_last_exception
    raise _exception[1]
  File "C:\Users\HP\Documents\Axsos_academy\Django\djangoPy3Env\lib\site-packages\django\core\management\__init__.py", line 337, in execute
    autoreload.check_errors(django.setup)()
  File "C:\Users\HP\Documents\Axsos_academy\Django\djangoPy3Env\lib\site-packages\django\utils\autoreload.py", line 54, in wrapper
    fn(*args, **kwargs)
  File "C:\Users\HP\Documents\Axsos_academy\Django\djangoPy3Env\lib\site-packages\django\__init__.py", line 24, in setup
    apps.populate(settings.INSTALLED_APPS)
  File "C:\Users\HP\Documents\Axsos_academy\Django\djangoPy3Env\lib\site-packages\django\apps\registry.py", line 114, in populate
    app_config.import_models()
  File "C:\Users\HP\Documents\Axsos_academy\Django\djangoPy3Env\lib\site-packages\django\apps\config.py", line 211, in import_models
    self.models_module = import_module(models_module_name)
  File "C:\Users\HP\AppData\Local\Programs\Python\Python36-32\lib\importlib\__init__.py", line 126, in import_module
    return _bootstrap._gcd_import(name[level:], package, level)
  File "<frozen importlib._bootstrap>", line 994, in _gcd_import
  File "<frozen importlib._bootstrap>", line 971, in _find_and_load
  File "<frozen importlib._bootstrap>", line 955, in _find_and_load_unlocked
  File "<frozen importlib._bootstrap>", line 665, in _load_unlocked
  File "<frozen importlib._bootstrap_external>", line 674, in exec_module
  File "<frozen importlib._bootstrap_external>", line 781, in get_code
  File "<frozen importlib._bootstrap_external>", line 741, in source_to_code
  File "<frozen importlib._bootstrap>", line 219, in _call_with_frames_removed
  File "C:\Users\HP\Documents\Axsos_academy\Django\django_intro\Dojoservey\dojo_servey\models.py", line 8
    class (models.Model):
          ^
SyntaxError: invalid syntax

C:\Users\HP\Documents\Axsos_academy\Django\django_intro\Dojoservey\dojo_servey\models.py changed, reloading.
Watching for file changes with StatReloader
Exception in thread django-main-thread:
Traceback (most recent call last):
  File "C:\Users\HP\AppData\Local\Programs\Python\Python36-32\lib\threading.py", line 916, in _bootstrap_inner
    self.run()
  File "C:\Users\HP\AppData\Local\Programs\Python\Python36-32\lib\threading.py", line 864, in run
    self._target(*self._args, **self._kwargs)
  File "C:\Users\HP\Documents\Axsos_academy\Django\djangoPy3Env\lib\site-packages\django\utils\autoreload.py", line 54, in wrapper
    fn(*args, **kwargs)
  File "C:\Users\HP\Documents\Axsos_academy\Django\djangoPy3Env\lib\site-packages\django\core\management\commands\runserver.py", line 109, in inner_run
    autoreload.raise_last_exception()
  File "C:\Users\HP\Documents\Axsos_academy\Django\djangoPy3Env\lib\site-packages\django\utils\autoreload.py", line 77, in raise_last_exception
    raise _exception[1]
  File "C:\Users\HP\Documents\Axsos_academy\Django\djangoPy3Env\lib\site-packages\django\core\management\__init__.py", line 337, in execute
    autoreload.check_errors(django.setup)()
  File "C:\Users\HP\Documents\Axsos_academy\Django\djangoPy3Env\lib\site-packages\django\utils\autoreload.py", line 54, in wrapper
    fn(*args, **kwargs)
  File "C:\Users\HP\Documents\Axsos_academy\Django\djangoPy3Env\lib\site-packages\django\__init__.py", line 24, in setup
    apps.populate(settings.INSTALLED_APPS)
  File "C:\Users\HP\Documents\Axsos_academy\Django\djangoPy3Env\lib\site-packages\django\apps\registry.py", line 114, in populate
    app_config.import_models()
  File "C:\Users\HP\Documents\Axsos_academy\Django\djangoPy3Env\lib\site-packages\django\apps\config.py", line 211, in import_models
    self.models_module = import_module(models_module_name)
  File "C:\Users\HP\AppData\Local\Programs\Python\Python36-32\lib\importlib\__init__.py", line 126, in import_module
    return _bootstrap._gcd_import(name[level:], package, level)
  File "<frozen importlib._bootstrap>", line 994, in _gcd_import
  File "<frozen importlib._bootstrap>", line 971, in _find_and_load
  File "<frozen importlib._bootstrap>", line 955, in _find_and_load_unlocked
  File "<frozen importlib._bootstrap>", line 665, in _load_unlocked
  File "<frozen importlib._bootstrap_external>", line 674, in exec_module
  File "<frozen importlib._bootstrap_external>", line 781, in get_code
  File "<frozen importlib._bootstrap_external>", line 741, in source_to_code
  File "<frozen importlib._bootstrap>", line 219, in _call_with_frames_removed
  File "C:\Users\HP\Documents\Axsos_academy\Django\django_intro\Dojoservey\dojo_servey\models.py", line 10
    description = models.TextField()
              ^
SyntaxError: invalid character in identifier

C:\Users\HP\Documents\Axsos_academy\Django\django_intro\Dojoservey\dojo_servey\models.py changed, reloading.
Watching for file changes with StatReloader
Exception in thread django-main-thread:
Traceback (most recent call last):
  File "C:\Users\HP\AppData\Local\Programs\Python\Python36-32\lib\threading.py", line 916, in _bootstrap_inner
    self.run()
  File "C:\Users\HP\AppData\Local\Programs\Python\Python36-32\lib\threading.py", line 864, in run
    self._target(*self._args, **self._kwargs)
  File "C:\Users\HP\Documents\Axsos_academy\Django\djangoPy3Env\lib\site-packages\django\utils\autoreload.py", line 54, in wrapper
    fn(*args, **kwargs)
  File "C:\Users\HP\Documents\Axsos_academy\Django\djangoPy3Env\lib\site-packages\django\core\management\commands\runserver.py", line 109, in inner_run
    autoreload.raise_last_exception()
  File "C:\Users\HP\Documents\Axsos_academy\Django\djangoPy3Env\lib\site-packages\django\utils\autoreload.py", line 77, in raise_last_exception
    raise _exception[1]
  File "C:\Users\HP\Documents\Axsos_academy\Django\djangoPy3Env\lib\site-packages\django\core\management\__init__.py", line 337, in execute
    autoreload.check_errors(django.setup)()
  File "C:\Users\HP\Documents\Axsos_academy\Django\djangoPy3Env\lib\site-packages\django\utils\autoreload.py", line 54, in wrapper
    fn(*args, **kwargs)
  File "C:\Users\HP\Documents\Axsos_academy\Django\djangoPy3Env\lib\site-packages\django\__init__.py", line 24, in setup
    apps.populate(settings.INSTALLED_APPS)
  File "C:\Users\HP\Documents\Axsos_academy\Django\djangoPy3Env\lib\site-packages\django\apps\registry.py", line 114, in populate
    app_config.import_models()
  File "C:\Users\HP\Documents\Axsos_academy\Django\djangoPy3Env\lib\site-packages\django\apps\config.py", line 211, in import_models
    self.models_module = import_module(models_module_name)
  File "C:\Users\HP\AppData\Local\Programs\Python\Python36-32\lib\importlib\__init__.py", line 126, in import_module
    return _bootstrap._gcd_import(name[level:], package, level)
  File "<frozen importlib._bootstrap>", line 994, in _gcd_import
  File "<frozen importlib._bootstrap>", line 971, in _find_and_load
  File "<frozen importlib._bootstrap>", line 955, in _find_and_load_unlocked
  File "<frozen importlib._bootstrap>", line 665, in _load_unlocked
  File "<frozen importlib._bootstrap_external>", line 674, in exec_module
  File "<frozen importlib._bootstrap_external>", line 781, in get_code
  File "<frozen importlib._bootstrap_external>", line 741, in source_to_code
  File "<frozen importlib._bootstrap>", line 219, in _call_with_frames_removed
  File "C:\Users\HP\Documents\Axsos_academy\Django\django_intro\Dojoservey\dojo_servey\models.py", line 10
    f= models.TextField()
    ^
SyntaxError: invalid character in identifier

C:\Users\HP\Documents\Axsos_academy\Django\django_intro\Dojoservey\dojo_servey\models.py changed, reloading.
Watching for file changes with StatReloader
Exception in thread django-main-thread:
Traceback (most recent call last):
  File "C:\Users\HP\AppData\Local\Programs\Python\Python36-32\lib\threading.py", line 916, in _bootstrap_inner
    self.run()
  File "C:\Users\HP\AppData\Local\Programs\Python\Python36-32\lib\threading.py", line 864, in run
    self._target(*self._args, **self._kwargs)
  File "C:\Users\HP\Documents\Axsos_academy\Django\djangoPy3Env\lib\site-packages\django\utils\autoreload.py", line 54, in wrapper
    fn(*args, **kwargs)
  File "C:\Users\HP\Documents\Axsos_academy\Django\djangoPy3Env\lib\site-packages\django\core\management\commands\runserver.py", line 109, in inner_run
    autoreload.raise_last_exception()
  File "C:\Users\HP\Documents\Axsos_academy\Django\djangoPy3Env\lib\site-packages\django\utils\autoreload.py", line 77, in raise_last_exception
    raise _exception[1]
  File "C:\Users\HP\Documents\Axsos_academy\Django\djangoPy3Env\lib\site-packages\django\core\management\__init__.py", line 337, in execute
    autoreload.check_errors(django.setup)()
  File "C:\Users\HP\Documents\Axsos_academy\Django\djangoPy3Env\lib\site-packages\django\utils\autoreload.py", line 54, in wrapper
    fn(*args, **kwargs)
  File "C:\Users\HP\Documents\Axsos_academy\Django\djangoPy3Env\lib\site-packages\django\__init__.py", line 24, in setup
    apps.populate(settings.INSTALLED_APPS)
  File "C:\Users\HP\Documents\Axsos_academy\Django\djangoPy3Env\lib\site-packages\django\apps\registry.py", line 114, in populate
    app_config.import_models()
  File "C:\Users\HP\Documents\Axsos_academy\Django\djangoPy3Env\lib\site-packages\django\apps\config.py", line 211, in import_models
    self.models_module = import_module(models_module_name)
  File "C:\Users\HP\AppData\Local\Programs\Python\Python36-32\lib\importlib\__init__.py", line 126, in import_module
    return _bootstrap._gcd_import(name[level:], package, level)
  File "<frozen importlib._bootstrap>", line 994, in _gcd_import
  File "<frozen importlib._bootstrap>", line 971, in _find_and_load
  File "<frozen importlib._bootstrap>", line 955, in _find_and_load_unlocked
  File "<frozen importlib._bootstrap>", line 665, in _load_unlocked
  File "<frozen importlib._bootstrap_external>", line 674, in exec_module
  File "<frozen importlib._bootstrap_external>", line 781, in get_code
  File "<frozen importlib._bootstrap_external>", line 741, in source_to_code
  File "<frozen importlib._bootstrap>", line 219, in _call_with_frames_removed
  File "C:\Users\HP\Documents\Axsos_academy\Django\django_intro\Dojoservey\dojo_servey\models.py", line 10
    fi= models.TextField()
     ^
SyntaxError: invalid character in identifier

C:\Users\HP\Documents\Axsos_academy\Django\django_intro\Dojoservey\dojo_servey\models.py changed, reloading.
Watching for file changes with StatReloader
Exception in thread django-main-thread:
Traceback (most recent call last):
  File "C:\Users\HP\AppData\Local\Programs\Python\Python36-32\lib\threading.py", line 916, in _bootstrap_inner
    self.run()
  File "C:\Users\HP\AppData\Local\Programs\Python\Python36-32\lib\threading.py", line 864, in run
    self._target(*self._args, **self._kwargs)
  File "C:\Users\HP\Documents\Axsos_academy\Django\djangoPy3Env\lib\site-packages\django\utils\autoreload.py", line 54, in wrapper
    fn(*args, **kwargs)
  File "C:\Users\HP\Documents\Axsos_academy\Django\djangoPy3Env\lib\site-packages\django\core\management\commands\runserver.py", line 109, in inner_run
    autoreload.raise_last_exception()
  File "C:\Users\HP\Documents\Axsos_academy\Django\djangoPy3Env\lib\site-packages\django\utils\autoreload.py", line 77, in raise_last_exception
    raise _exception[1]
  File "C:\Users\HP\Documents\Axsos_academy\Django\djangoPy3Env\lib\site-packages\django\core\management\__init__.py", line 337, in execute
    autoreload.check_errors(django.setup)()
  File "C:\Users\HP\Documents\Axsos_academy\Django\djangoPy3Env\lib\site-packages\django\utils\autoreload.py", line 54, in wrapper
    fn(*args, **kwargs)
  File "C:\Users\HP\Documents\Axsos_academy\Django\djangoPy3Env\lib\site-packages\django\__init__.py", line 24, in setup
    apps.populate(settings.INSTALLED_APPS)
  File "C:\Users\HP\Documents\Axsos_academy\Django\djangoPy3Env\lib\site-packages\django\apps\registry.py", line 114, in populate
    app_config.import_models()
  File "C:\Users\HP\Documents\Axsos_academy\Django\djangoPy3Env\lib\site-packages\django\apps\config.py", line 211, in import_models
    self.models_module = import_module(models_module_name)
  File "C:\Users\HP\AppData\Local\Programs\Python\Python36-32\lib\importlib\__init__.py", line 126, in import_module
    return _bootstrap._gcd_import(name[level:], package, level)
  File "<frozen importlib._bootstrap>", line 994, in _gcd_import
  File "<frozen importlib._bootstrap>", line 971, in _find_and_load
  File "<frozen importlib._bootstrap>", line 955, in _find_and_load_unlocked
  File "<frozen importlib._bootstrap>", line 665, in _load_unlocked
  File "<frozen importlib._bootstrap_external>", line 674, in exec_module
  File "<frozen importlib._bootstrap_external>", line 781, in get_code
  File "<frozen importlib._bootstrap_external>", line 741, in source_to_code
  File "<frozen importlib._bootstrap>", line 219, in _call_with_frames_removed
  File "C:\Users\HP\Documents\Axsos_academy\Django\django_intro\Dojoservey\dojo_servey\models.py", line 10
    fi= models.TextField()
     ^
SyntaxError: invalid character in identifier

C:\Users\HP\Documents\Axsos_academy\Django\django_intro\Dojoservey\dojo_servey\models.py changed, reloading.
Watching for file changes with StatReloader
Exception in thread django-main-thread:
Traceback (most recent call last):
  File "C:\Users\HP\AppData\Local\Programs\Python\Python36-32\lib\threading.py", line 916, in _bootstrap_inner
    self.run()
  File "C:\Users\HP\AppData\Local\Programs\Python\Python36-32\lib\threading.py", line 864, in run
    self._target(*self._args, **self._kwargs)
  File "C:\Users\HP\Documents\Axsos_academy\Django\djangoPy3Env\lib\site-packages\django\utils\autoreload.py", line 54, in wrapper
    fn(*args, **kwargs)
  File "C:\Users\HP\Documents\Axsos_academy\Django\djangoPy3Env\lib\site-packages\django\core\management\commands\runserver.py", line 109, in inner_run
    autoreload.raise_last_exception()
  File "C:\Users\HP\Documents\Axsos_academy\Django\djangoPy3Env\lib\site-packages\django\utils\autoreload.py", line 77, in raise_last_exception
    raise _exception[1]
  File "C:\Users\HP\Documents\Axsos_academy\Django\djangoPy3Env\lib\site-packages\django\core\management\__init__.py", line 337, in execute
    autoreload.check_errors(django.setup)()
  File "C:\Users\HP\Documents\Axsos_academy\Django\djangoPy3Env\lib\site-packages\django\utils\autoreload.py", line 54, in wrapper
    fn(*args, **kwargs)
  File "C:\Users\HP\Documents\Axsos_academy\Django\djangoPy3Env\lib\site-packages\django\__init__.py", line 24, in setup
    apps.populate(settings.INSTALLED_APPS)
  File "C:\Users\HP\Documents\Axsos_academy\Django\djangoPy3Env\lib\site-packages\django\apps\registry.py", line 114, in populate
    app_config.import_models()
  File "C:\Users\HP\Documents\Axsos_academy\Django\djangoPy3Env\lib\site-packages\django\apps\config.py", line 211, in import_models
    self.models_module = import_module(models_module_name)
  File "C:\Users\HP\AppData\Local\Programs\Python\Python36-32\lib\importlib\__init__.py", line 126, in import_module
    return _bootstrap._gcd_import(name[level:], package, level)
  File "<frozen importlib._bootstrap>", line 994, in _gcd_import
  File "<frozen importlib._bootstrap>", line 971, in _find_and_load
  File "<frozen importlib._bootstrap>", line 955, in _find_and_load_unlocked
  File "<frozen importlib._bootstrap>", line 665, in _load_unlocked
  File "<frozen importlib._bootstrap_external>", line 674, in exec_module
  File "<frozen importlib._bootstrap_external>", line 781, in get_code
  File "<frozen importlib._bootstrap_external>", line 741, in source_to_code
  File "<frozen importlib._bootstrap>", line 219, in _call_with_frames_removed
  File "C:\Users\HP\Documents\Axsos_academy\Django\django_intro\Dojoservey\dojo_servey\models.py", line 10
    first_namme= models.TextField()
              ^
SyntaxError: invalid character in identifier

C:\Users\HP\Documents\Axsos_academy\Django\django_intro\Dojoservey\dojo_servey\models.py changed, reloading.
Watching for file changes with StatReloader
Exception in thread django-main-thread:
Traceback (most recent call last):
  File "C:\Users\HP\AppData\Local\Programs\Python\Python36-32\lib\threading.py", line 916, in _bootstrap_inner
    self.run()
  File "C:\Users\HP\AppData\Local\Programs\Python\Python36-32\lib\threading.py", line 864, in run
    self._target(*self._args, **self._kwargs)
  File "C:\Users\HP\Documents\Axsos_academy\Django\djangoPy3Env\lib\site-packages\django\utils\autoreload.py", line 54, in wrapper
    fn(*args, **kwargs)
  File "C:\Users\HP\Documents\Axsos_academy\Django\djangoPy3Env\lib\site-packages\django\core\management\commands\runserver.py", line 109, in inner_run
    autoreload.raise_last_exception()
  File "C:\Users\HP\Documents\Axsos_academy\Django\djangoPy3Env\lib\site-packages\django\utils\autoreload.py", line 77, in raise_last_exception
    raise _exception[1]
  File "C:\Users\HP\Documents\Axsos_academy\Django\djangoPy3Env\lib\site-packages\django\core\management\__init__.py", line 337, in execute
    autoreload.check_errors(django.setup)()
  File "C:\Users\HP\Documents\Axsos_academy\Django\djangoPy3Env\lib\site-packages\django\utils\autoreload.py", line 54, in wrapper
    fn(*args, **kwargs)
  File "C:\Users\HP\Documents\Axsos_academy\Django\djangoPy3Env\lib\site-packages\django\__init__.py", line 24, in setup
    apps.populate(settings.INSTALLED_APPS)
  File "C:\Users\HP\Documents\Axsos_academy\Django\djangoPy3Env\lib\site-packages\django\apps\registry.py", line 114, in populate
    app_config.import_models()
  File "C:\Users\HP\Documents\Axsos_academy\Django\djangoPy3Env\lib\site-packages\django\apps\config.py", line 211, in import_models
    self.models_module = import_module(models_module_name)
  File "C:\Users\HP\AppData\Local\Programs\Python\Python36-32\lib\importlib\__init__.py", line 126, in import_module
    return _bootstrap._gcd_import(name[level:], package, level)
  File "<frozen importlib._bootstrap>", line 994, in _gcd_import
  File "<frozen importlib._bootstrap>", line 971, in _find_and_load
  File "<frozen importlib._bootstrap>", line 955, in _find_and_load_unlocked
  File "<frozen importlib._bootstrap>", line 665, in _load_unlocked
  File "<frozen importlib._bootstrap_external>", line 674, in exec_module
  File "<frozen importlib._bootstrap_external>", line 781, in get_code
  File "<frozen importlib._bootstrap_external>", line 741, in source_to_code
  File "<frozen importlib._bootstrap>", line 219, in _call_with_frames_removed
  File "C:\Users\HP\Documents\Axsos_academy\Django\django_intro\Dojoservey\dojo_servey\models.py", line 10
    first_name= models.TextField()
             ^
SyntaxError: invalid character in identifier

C:\Users\HP\Documents\Axsos_academy\Django\django_intro\Dojoservey\dojo_servey\models.py changed, reloading.
Watching for file changes with StatReloader
Exception in thread django-main-thread:
Traceback (most recent call last):
  File "C:\Users\HP\AppData\Local\Programs\Python\Python36-32\lib\threading.py", line 916, in _bootstrap_inner
    self.run()
  File "C:\Users\HP\AppData\Local\Programs\Python\Python36-32\lib\threading.py", line 864, in run
    self._target(*self._args, **self._kwargs)
  File "C:\Users\HP\Documents\Axsos_academy\Django\djangoPy3Env\lib\site-packages\django\utils\autoreload.py", line 54, in wrapper
    fn(*args, **kwargs)
  File "C:\Users\HP\Documents\Axsos_academy\Django\djangoPy3Env\lib\site-packages\django\core\management\commands\runserver.py", line 109, in inner_run
    autoreload.raise_last_exception()
  File "C:\Users\HP\Documents\Axsos_academy\Django\djangoPy3Env\lib\site-packages\django\utils\autoreload.py", line 77, in raise_last_exception
    raise _exception[1]
  File "C:\Users\HP\Documents\Axsos_academy\Django\djangoPy3Env\lib\site-packages\django\core\management\__init__.py", line 337, in execute
    autoreload.check_errors(django.setup)()
  File "C:\Users\HP\Documents\Axsos_academy\Django\djangoPy3Env\lib\site-packages\django\utils\autoreload.py", line 54, in wrapper
    fn(*args, **kwargs)
  File "C:\Users\HP\Documents\Axsos_academy\Django\djangoPy3Env\lib\site-packages\django\__init__.py", line 24, in setup
    apps.populate(settings.INSTALLED_APPS)
  File "C:\Users\HP\Documents\Axsos_academy\Django\djangoPy3Env\lib\site-packages\django\apps\registry.py", line 114, in populate
    app_config.import_models()
  File "C:\Users\HP\Documents\Axsos_academy\Django\djangoPy3Env\lib\site-packages\django\apps\config.py", line 211, in import_models
    self.models_module = import_module(models_module_name)
  File "C:\Users\HP\AppData\Local\Programs\Python\Python36-32\lib\importlib\__init__.py", line 126, in import_module
    return _bootstrap._gcd_import(name[level:], package, level)
  File "<frozen importlib._bootstrap>", line 994, in _gcd_import
  File "<frozen importlib._bootstrap>", line 971, in _find_and_load
  File "<frozen importlib._bootstrap>", line 955, in _find_and_load_unlocked
  File "<frozen importlib._bootstrap>", line 665, in _load_unlocked
  File "<frozen importlib._bootstrap_external>", line 674, in exec_module
  File "<frozen importlib._bootstrap_external>", line 781, in get_code
  File "<frozen importlib._bootstrap_external>", line 741, in source_to_code
  File "<frozen importlib._bootstrap>", line 219, in _call_with_frames_removed
  File "C:\Users\HP\Documents\Axsos_academy\Django\django_intro\Dojoservey\dojo_servey\models.py", line 10
    first_name= CharField(max_length=45)
             ^
SyntaxError: invalid character in identifier

C:\Users\HP\Documents\Axsos_academy\Django\django_intro\Dojoservey\dojo_servey\models.py changed, reloading.
Watching for file changes with StatReloader
Exception in thread django-main-thread:
Traceback (most recent call last):
  File "C:\Users\HP\AppData\Local\Programs\Python\Python36-32\lib\threading.py", line 916, in _bootstrap_inner
    self.run()
  File "C:\Users\HP\AppData\Local\Programs\Python\Python36-32\lib\threading.py", line 864, in run
    self._target(*self._args, **self._kwargs)
  File "C:\Users\HP\Documents\Axsos_academy\Django\djangoPy3Env\lib\site-packages\django\utils\autoreload.py", line 54, in wrapper
    fn(*args, **kwargs)
  File "C:\Users\HP\Documents\Axsos_academy\Django\djangoPy3Env\lib\site-packages\django\core\management\commands\runserver.py", line 109, in inner_run
    autoreload.raise_last_exception()
  File "C:\Users\HP\Documents\Axsos_academy\Django\djangoPy3Env\lib\site-packages\django\utils\autoreload.py", line 77, in raise_last_exception
    raise _exception[1]
  File "C:\Users\HP\Documents\Axsos_academy\Django\djangoPy3Env\lib\site-packages\django\core\management\__init__.py", line 337, in execute
    autoreload.check_errors(django.setup)()
  File "C:\Users\HP\Documents\Axsos_academy\Django\djangoPy3Env\lib\site-packages\django\utils\autoreload.py", line 54, in wrapper
    fn(*args, **kwargs)
  File "C:\Users\HP\Documents\Axsos_academy\Django\djangoPy3Env\lib\site-packages\django\__init__.py", line 24, in setup
    apps.populate(settings.INSTALLED_APPS)
  File "C:\Users\HP\Documents\Axsos_academy\Django\djangoPy3Env\lib\site-packages\django\apps\registry.py", line 114, in populate
    app_config.import_models()
  File "C:\Users\HP\Documents\Axsos_academy\Django\djangoPy3Env\lib\site-packages\django\apps\config.py", line 211, in import_models
    self.models_module = import_module(models_module_name)
  File "C:\Users\HP\AppData\Local\Programs\Python\Python36-32\lib\importlib\__init__.py", line 126, in import_module
    return _bootstrap._gcd_import(name[level:], package, level)
  File "<frozen importlib._bootstrap>", line 994, in _gcd_import
  File "<frozen importlib._bootstrap>", line 971, in _find_and_load
  File "<frozen importlib._bootstrap>", line 955, in _find_and_load_unlocked
  File "<frozen importlib._bootstrap>", line 665, in _load_unlocked
  File "<frozen importlib._bootstrap_external>", line 674, in exec_module
  File "<frozen importlib._bootstrap_external>", line 781, in get_code
  File "<frozen importlib._bootstrap_external>", line 741, in source_to_code
  File "<frozen importlib._bootstrap>", line 219, in _call_with_frames_removed
  File "C:\Users\HP\Documents\Axsos_academy\Django\django_intro\Dojoservey\dojo_servey\models.py", line 10
    first_name= CharField(max_length=45)
             ^
SyntaxError: invalid character in identifier

C:\Users\HP\Documents\Axsos_academy\Django\django_intro\Dojoservey\dojo_servey\models.py changed, reloading.
Watching for file changes with StatReloader
Exception in thread django-main-thread:
Traceback (most recent call last):
  File "C:\Users\HP\AppData\Local\Programs\Python\Python36-32\lib\threading.py", line 916, in _bootstrap_inner
    self.run()
  File "C:\Users\HP\AppData\Local\Programs\Python\Python36-32\lib\threading.py", line 864, in run
    self._target(*self._args, **self._kwargs)
  File "C:\Users\HP\Documents\Axsos_academy\Django\djangoPy3Env\lib\site-packages\django\utils\autoreload.py", line 54, in wrapper
    fn(*args, **kwargs)
  File "C:\Users\HP\Documents\Axsos_academy\Django\djangoPy3Env\lib\site-packages\django\core\management\commands\runserver.py", line 109, in inner_run
    autoreload.raise_last_exception()
  File "C:\Users\HP\Documents\Axsos_academy\Django\djangoPy3Env\lib\site-packages\django\utils\autoreload.py", line 77, in raise_last_exception
    raise _exception[1]
  File "C:\Users\HP\Documents\Axsos_academy\Django\djangoPy3Env\lib\site-packages\django\core\management\__init__.py", line 337, in execute
    autoreload.check_errors(django.setup)()
  File "C:\Users\HP\Documents\Axsos_academy\Django\djangoPy3Env\lib\site-packages\django\utils\autoreload.py", line 54, in wrapper
    fn(*args, **kwargs)
  File "C:\Users\HP\Documents\Axsos_academy\Django\djangoPy3Env\lib\site-packages\django\__init__.py", line 24, in setup
    apps.populate(settings.INSTALLED_APPS)
  File "C:\Users\HP\Documents\Axsos_academy\Django\djangoPy3Env\lib\site-packages\django\apps\registry.py", line 114, in populate
    app_config.import_models()
  File "C:\Users\HP\Documents\Axsos_academy\Django\djangoPy3Env\lib\site-packages\django\apps\config.py", line 211, in import_models
    self.models_module = import_module(models_module_name)
  File "C:\Users\HP\AppData\Local\Programs\Python\Python36-32\lib\importlib\__init__.py", line 126, in import_module
    return _bootstrap._gcd_import(name[level:], package, level)
  File "<frozen importlib._bootstrap>", line 994, in _gcd_import
  File "<frozen importlib._bootstrap>", line 971, in _find_and_load
  File "<frozen importlib._bootstrap>", line 955, in _find_and_load_unlocked
  File "<frozen importlib._bootstrap>", line 665, in _load_unlocked
  File "<frozen importlib._bootstrap_external>", line 674, in exec_module
  File "<frozen importlib._bootstrap_external>", line 781, in get_code
  File "<frozen importlib._bootstrap_external>", line 741, in source_to_code
  File "<frozen importlib._bootstrap>", line 219, in _call_with_frames_removed
  File "C:\Users\HP\Documents\Axsos_academy\Django\django_intro\Dojoservey\dojo_servey\models.py", line 10
    first_name= CharField(max_length=45)
             ^
SyntaxError: invalid character in identifier

C:\Users\HP\Documents\Axsos_academy\Django\django_intro\Dojoservey\dojo_servey\models.py changed, reloading.
Watching for file changes with StatReloader
Exception in thread django-main-thread:
Traceback (most recent call last):
  File "C:\Users\HP\AppData\Local\Programs\Python\Python36-32\lib\threading.py", line 916, in _bootstrap_inner
    self.run()
  File "C:\Users\HP\AppData\Local\Programs\Python\Python36-32\lib\threading.py", line 864, in run
    self._target(*self._args, **self._kwargs)
  File "C:\Users\HP\Documents\Axsos_academy\Django\djangoPy3Env\lib\site-packages\django\utils\autoreload.py", line 54, in wrapper
    fn(*args, **kwargs)
  File "C:\Users\HP\Documents\Axsos_academy\Django\djangoPy3Env\lib\site-packages\django\core\management\commands\runserver.py", line 109, in inner_run
    autoreload.raise_last_exception()
  File "C:\Users\HP\Documents\Axsos_academy\Django\djangoPy3Env\lib\site-packages\django\utils\autoreload.py", line 77, in raise_last_exception
    raise _exception[1]
  File "C:\Users\HP\Documents\Axsos_academy\Django\djangoPy3Env\lib\site-packages\django\core\management\__init__.py", line 337, in execute
    autoreload.check_errors(django.setup)()
  File "C:\Users\HP\Documents\Axsos_academy\Django\djangoPy3Env\lib\site-packages\django\utils\autoreload.py", line 54, in wrapper
    fn(*args, **kwargs)
  File "C:\Users\HP\Documents\Axsos_academy\Django\djangoPy3Env\lib\site-packages\django\__init__.py", line 24, in setup
    apps.populate(settings.INSTALLED_APPS)
  File "C:\Users\HP\Documents\Axsos_academy\Django\djangoPy3Env\lib\site-packages\django\apps\registry.py", line 114, in populate
    app_config.import_models()
  File "C:\Users\HP\Documents\Axsos_academy\Django\djangoPy3Env\lib\site-packages\django\apps\config.py", line 211, in import_models
    self.models_module = import_module(models_module_name)
  File "C:\Users\HP\AppData\Local\Programs\Python\Python36-32\lib\importlib\__init__.py", line 126, in import_module
    return _bootstrap._gcd_import(name[level:], package, level)
  File "<frozen importlib._bootstrap>", line 994, in _gcd_import
  File "<frozen importlib._bootstrap>", line 971, in _find_and_load
  File "<frozen importlib._bootstrap>", line 955, in _find_and_load_unlocked
  File "<frozen importlib._bootstrap>", line 665, in _load_unlocked
  File "<frozen importlib._bootstrap_external>", line 674, in exec_module
  File "<frozen importlib._bootstrap_external>", line 781, in get_code
  File "<frozen importlib._bootstrap_external>", line 741, in source_to_code
  File "<frozen importlib._bootstrap>", line 219, in _call_with_frames_removed
  File "C:\Users\HP\Documents\Axsos_academy\Django\django_intro\Dojoservey\dojo_servey\models.py", line 11
    last_name= CharField(max_length=45)
            ^
SyntaxError: invalid character in identifier

C:\Users\HP\Documents\Axsos_academy\Django\django_intro\Dojoservey\dojo_servey\models.py changed, reloading.
Watching for file changes with StatReloader
Exception in thread django-main-thread:
Traceback (most recent call last):
  File "C:\Users\HP\AppData\Local\Programs\Python\Python36-32\lib\threading.py", line 916, in _bootstrap_inner
    self.run()
  File "C:\Users\HP\AppData\Local\Programs\Python\Python36-32\lib\threading.py", line 864, in run
    self._target(*self._args, **self._kwargs)
  File "C:\Users\HP\Documents\Axsos_academy\Django\djangoPy3Env\lib\site-packages\django\utils\autoreload.py", line 54, in wrapper
    fn(*args, **kwargs)
  File "C:\Users\HP\Documents\Axsos_academy\Django\djangoPy3Env\lib\site-packages\django\core\management\commands\runserver.py", line 109, in inner_run
    autoreload.raise_last_exception()
  File "C:\Users\HP\Documents\Axsos_academy\Django\djangoPy3Env\lib\site-packages\django\utils\autoreload.py", line 77, in raise_last_exception
    raise _exception[1]
  File "C:\Users\HP\Documents\Axsos_academy\Django\djangoPy3Env\lib\site-packages\django\core\management\__init__.py", line 337, in execute
    autoreload.check_errors(django.setup)()
  File "C:\Users\HP\Documents\Axsos_academy\Django\djangoPy3Env\lib\site-packages\django\utils\autoreload.py", line 54, in wrapper
    fn(*args, **kwargs)
  File "C:\Users\HP\Documents\Axsos_academy\Django\djangoPy3Env\lib\site-packages\django\__init__.py", line 24, in setup
    apps.populate(settings.INSTALLED_APPS)
  File "C:\Users\HP\Documents\Axsos_academy\Django\djangoPy3Env\lib\site-packages\django\apps\registry.py", line 114, in populate
    app_config.import_models()
  File "C:\Users\HP\Documents\Axsos_academy\Django\djangoPy3Env\lib\site-packages\django\apps\config.py", line 211, in import_models
    self.models_module = import_module(models_module_name)
  File "C:\Users\HP\AppData\Local\Programs\Python\Python36-32\lib\importlib\__init__.py", line 126, in import_module
    return _bootstrap._gcd_import(name[level:], package, level)
  File "<frozen importlib._bootstrap>", line 994, in _gcd_import
  File "<frozen importlib._bootstrap>", line 971, in _find_and_load
  File "<frozen importlib._bootstrap>", line 955, in _find_and_load_unlocked
  File "<frozen importlib._bootstrap>", line 665, in _load_unlocked
  File "<frozen importlib._bootstrap_external>", line 674, in exec_module
  File "<frozen importlib._bootstrap_external>", line 781, in get_code
  File "<frozen importlib._bootstrap_external>", line 741, in source_to_code
  File "<frozen importlib._bootstrap>", line 219, in _call_with_frames_removed
  File "C:\Users\HP\Documents\Axsos_academy\Django\django_intro\Dojoservey\dojo_servey\models.py", line 12
    duration = models.IntegerField()
           ^
SyntaxError: invalid character in identifier

C:\Users\HP\Documents\Axsos_academy\Django\django_intro\Dojoservey\dojo_servey\models.py changed, reloading.
Watching for file changes with StatReloader
Exception in thread django-main-thread:
Traceback (most recent call last):
  File "C:\Users\HP\AppData\Local\Programs\Python\Python36-32\lib\threading.py", line 916, in _bootstrap_inner
    self.run()
  File "C:\Users\HP\AppData\Local\Programs\Python\Python36-32\lib\threading.py", line 864, in run
    self._target(*self._args, **self._kwargs)
  File "C:\Users\HP\Documents\Axsos_academy\Django\djangoPy3Env\lib\site-packages\django\utils\autoreload.py", line 54, in wrapper
    fn(*args, **kwargs)
  File "C:\Users\HP\Documents\Axsos_academy\Django\djangoPy3Env\lib\site-packages\django\core\management\commands\runserver.py", line 109, in inner_run
    autoreload.raise_last_exception()
  File "C:\Users\HP\Documents\Axsos_academy\Django\djangoPy3Env\lib\site-packages\django\utils\autoreload.py", line 77, in raise_last_exception
    raise _exception[1]
  File "C:\Users\HP\Documents\Axsos_academy\Django\djangoPy3Env\lib\site-packages\django\core\management\__init__.py", line 337, in execute
    autoreload.check_errors(django.setup)()
  File "C:\Users\HP\Documents\Axsos_academy\Django\djangoPy3Env\lib\site-packages\django\utils\autoreload.py", line 54, in wrapper
    fn(*args, **kwargs)
  File "C:\Users\HP\Documents\Axsos_academy\Django\djangoPy3Env\lib\site-packages\django\__init__.py", line 24, in setup
    apps.populate(settings.INSTALLED_APPS)
  File "C:\Users\HP\Documents\Axsos_academy\Django\djangoPy3Env\lib\site-packages\django\apps\registry.py", line 114, in populate
    app_config.import_models()
  File "C:\Users\HP\Documents\Axsos_academy\Django\djangoPy3Env\lib\site-packages\django\apps\config.py", line 211, in import_models
    self.models_module = import_module(models_module_name)
  File "C:\Users\HP\AppData\Local\Programs\Python\Python36-32\lib\importlib\__init__.py", line 126, in import_module
    return _bootstrap._gcd_import(name[level:], package, level)
  File "<frozen importlib._bootstrap>", line 994, in _gcd_import
  File "<frozen importlib._bootstrap>", line 971, in _find_and_load
  File "<frozen importlib._bootstrap>", line 955, in _find_and_load_unlocked
  File "<frozen importlib._bootstrap>", line 665, in _load_unlocked
  File "<frozen importlib._bootstrap_external>", line 674, in exec_module
  File "<frozen importlib._bootstrap_external>", line 781, in get_code
  File "<frozen importlib._bootstrap_external>", line 741, in source_to_code
  File "<frozen importlib._bootstrap>", line 219, in _call_with_frames_removed
  File "C:\Users\HP\Documents\Axsos_academy\Django\django_intro\Dojoservey\dojo_servey\models.py", line 13
    created_at = models.DateTimeField(auto_now_add=True)
             ^
SyntaxError: invalid character in identifier

C:\Users\HP\Documents\Axsos_academy\Django\django_intro\Dojoservey\dojo_servey\models.py changed, reloading.
Watching for file changes with StatReloader
Exception in thread django-main-thread:
Traceback (most recent call last):
  File "C:\Users\HP\AppData\Local\Programs\Python\Python36-32\lib\threading.py", line 916, in _bootstrap_inner
    self.run()
  File "C:\Users\HP\AppData\Local\Programs\Python\Python36-32\lib\threading.py", line 864, in run
    self._target(*self._args, **self._kwargs)
  File "C:\Users\HP\Documents\Axsos_academy\Django\djangoPy3Env\lib\site-packages\django\utils\autoreload.py", line 54, in wrapper
    fn(*args, **kwargs)
  File "C:\Users\HP\Documents\Axsos_academy\Django\djangoPy3Env\lib\site-packages\django\core\management\commands\runserver.py", line 109, in inner_run
    autoreload.raise_last_exception()
  File "C:\Users\HP\Documents\Axsos_academy\Django\djangoPy3Env\lib\site-packages\django\utils\autoreload.py", line 77, in raise_last_exception
    raise _exception[1]
  File "C:\Users\HP\Documents\Axsos_academy\Django\djangoPy3Env\lib\site-packages\django\core\management\__init__.py", line 337, in execute
    autoreload.check_errors(django.setup)()
  File "C:\Users\HP\Documents\Axsos_academy\Django\djangoPy3Env\lib\site-packages\django\utils\autoreload.py", line 54, in wrapper
    fn(*args, **kwargs)
  File "C:\Users\HP\Documents\Axsos_academy\Django\djangoPy3Env\lib\site-packages\django\__init__.py", line 24, in setup
    apps.populate(settings.INSTALLED_APPS)
  File "C:\Users\HP\Documents\Axsos_academy\Django\djangoPy3Env\lib\site-packages\django\apps\registry.py", line 114, in populate
    app_config.import_models()
  File "C:\Users\HP\Documents\Axsos_academy\Django\djangoPy3Env\lib\site-packages\django\apps\config.py", line 211, in import_models
    self.models_module = import_module(models_module_name)
  File "C:\Users\HP\AppData\Local\Programs\Python\Python36-32\lib\importlib\__init__.py", line 126, in import_module
    return _bootstrap._gcd_import(name[level:], package, level)
  File "<frozen importlib._bootstrap>", line 994, in _gcd_import
  File "<frozen importlib._bootstrap>", line 971, in _find_and_load
  File "<frozen importlib._bootstrap>", line 955, in _find_and_load_unlocked
  File "<frozen importlib._bootstrap>", line 665, in _load_unlocked
  File "<frozen importlib._bootstrap_external>", line 674, in exec_module
  File "<frozen importlib._bootstrap_external>", line 781, in get_code
  File "<frozen importlib._bootstrap_external>", line 741, in source_to_code
  File "<frozen importlib._bootstrap>", line 219, in _call_with_frames_removed
  File "C:\Users\HP\Documents\Axsos_academy\Django\django_intro\Dojoservey\dojo_servey\models.py", line 14
    updated_at = models.DateTimeField(auto_now=True)
             ^
SyntaxError: invalid character in identifier

C:\Users\HP\Documents\Axsos_academy\Django\django_intro\Dojoservey\dojo_servey\models.py changed, reloading.
Watching for file changes with StatReloader
Exception in thread django-main-thread:
Traceback (most recent call last):
  File "C:\Users\HP\AppData\Local\Programs\Python\Python36-32\lib\threading.py", line 916, in _bootstrap_inner
    self.run()
  File "C:\Users\HP\AppData\Local\Programs\Python\Python36-32\lib\threading.py", line 864, in run
    self._target(*self._args, **self._kwargs)
  File "C:\Users\HP\Documents\Axsos_academy\Django\djangoPy3Env\lib\site-packages\django\utils\autoreload.py", line 54, in wrapper
    fn(*args, **kwargs)
  File "C:\Users\HP\Documents\Axsos_academy\Django\djangoPy3Env\lib\site-packages\django\core\management\commands\runserver.py", line 109, in inner_run
    autoreload.raise_last_exception()
  File "C:\Users\HP\Documents\Axsos_academy\Django\djangoPy3Env\lib\site-packages\django\utils\autoreload.py", line 77, in raise_last_exception
    raise _exception[1]
  File "C:\Users\HP\Documents\Axsos_academy\Django\djangoPy3Env\lib\site-packages\django\core\management\__init__.py", line 337, in execute
    autoreload.check_errors(django.setup)()
  File "C:\Users\HP\Documents\Axsos_academy\Django\djangoPy3Env\lib\site-packages\django\utils\autoreload.py", line 54, in wrapper
    fn(*args, **kwargs)
  File "C:\Users\HP\Documents\Axsos_academy\Django\djangoPy3Env\lib\site-packages\django\__init__.py", line 24, in setup
    apps.populate(settings.INSTALLED_APPS)
  File "C:\Users\HP\Documents\Axsos_academy\Django\djangoPy3Env\lib\site-packages\django\apps\registry.py", line 114, in populate
    app_config.import_models()
  File "C:\Users\HP\Documents\Axsos_academy\Django\djangoPy3Env\lib\site-packages\django\apps\config.py", line 211, in import_models
    self.models_module = import_module(models_module_name)
  File "C:\Users\HP\AppData\Local\Programs\Python\Python36-32\lib\importlib\__init__.py", line 126, in import_module
    return _bootstrap._gcd_import(name[level:], package, level)
  File "<frozen importlib._bootstrap>", line 994, in _gcd_import
  File "<frozen importlib._bootstrap>", line 971, in _find_and_load
  File "<frozen importlib._bootstrap>", line 955, in _find_and_load_unlocked
  File "<frozen importlib._bootstrap>", line 665, in _load_unlocked
  File "<frozen importlib._bootstrap_external>", line 678, in exec_module
  File "<frozen importlib._bootstrap>", line 219, in _call_with_frames_removed
  File "C:\Users\HP\Documents\Axsos_academy\Django\django_intro\Dojoservey\dojo_servey\models.py", line 9, in <module>
    class user(models.Model):
  File "C:\Users\HP\Documents\Axsos_academy\Django\django_intro\Dojoservey\dojo_servey\models.py", line 11, in user
    first_name= CharField(max_length=45)
NameError: name 'CharField' is not defined

C:\Users\HP\Documents\Axsos_academy\Django\django_intro\Dojoservey\dojo_servey\models.py changed, reloading.
Watching for file changes with StatReloader
Exception in thread django-main-thread:
Traceback (most recent call last):
  File "C:\Users\HP\AppData\Local\Programs\Python\Python36-32\lib\threading.py", line 916, in _bootstrap_inner
    self.run()
  File "C:\Users\HP\AppData\Local\Programs\Python\Python36-32\lib\threading.py", line 864, in run
    self._target(*self._args, **self._kwargs)
  File "C:\Users\HP\Documents\Axsos_academy\Django\djangoPy3Env\lib\site-packages\django\utils\autoreload.py", line 54, in wrapper
    fn(*args, **kwargs)
  File "C:\Users\HP\Documents\Axsos_academy\Django\djangoPy3Env\lib\site-packages\django\core\management\commands\runserver.py", line 109, in inner_run
    autoreload.raise_last_exception()
  File "C:\Users\HP\Documents\Axsos_academy\Django\djangoPy3Env\lib\site-packages\django\utils\autoreload.py", line 77, in raise_last_exception
    raise _exception[1]
  File "C:\Users\HP\Documents\Axsos_academy\Django\djangoPy3Env\lib\site-packages\django\core\management\__init__.py", line 337, in execute
    autoreload.check_errors(django.setup)()
  File "C:\Users\HP\Documents\Axsos_academy\Django\djangoPy3Env\lib\site-packages\django\utils\autoreload.py", line 54, in wrapper
    fn(*args, **kwargs)
  File "C:\Users\HP\Documents\Axsos_academy\Django\djangoPy3Env\lib\site-packages\django\__init__.py", line 24, in setup
    apps.populate(settings.INSTALLED_APPS)
  File "C:\Users\HP\Documents\Axsos_academy\Django\djangoPy3Env\lib\site-packages\django\apps\registry.py", line 114, in populate
    app_config.import_models()
  File "C:\Users\HP\Documents\Axsos_academy\Django\djangoPy3Env\lib\site-packages\django\apps\config.py", line 211, in import_models
    self.models_module = import_module(models_module_name)
  File "C:\Users\HP\AppData\Local\Programs\Python\Python36-32\lib\importlib\__init__.py", line 126, in import_module
    return _bootstrap._gcd_import(name[level:], package, level)
  File "<frozen importlib._bootstrap>", line 994, in _gcd_import
  File "<frozen importlib._bootstrap>", line 971, in _find_and_load
  File "<frozen importlib._bootstrap>", line 955, in _find_and_load_unlocked
  File "<frozen importlib._bootstrap>", line 665, in _load_unlocked
  File "<frozen importlib._bootstrap_external>", line 678, in exec_module
  File "<frozen importlib._bootstrap>", line 219, in _call_with_frames_removed
  File "C:\Users\HP\Documents\Axsos_academy\Django\django_intro\Dojoservey\dojo_servey\models.py", line 9, in <module>
    class user(models.Model):
  File "C:\Users\HP\Documents\Axsos_academy\Django\django_intro\Dojoservey\dojo_servey\models.py", line 11, in user
    first_name= CharField(max_length=45)
NameError: name 'CharField' is not defined

C:\Users\HP\Documents\Axsos_academy\Django\django_intro\Dojoservey\dojo_servey\models.py changed, reloading.
Watching for file changes with StatReloader
Exception in thread django-main-thread:
Traceback (most recent call last):
  File "C:\Users\HP\AppData\Local\Programs\Python\Python36-32\lib\threading.py", line 916, in _bootstrap_inner
    self.run()
  File "C:\Users\HP\AppData\Local\Programs\Python\Python36-32\lib\threading.py", line 864, in run
    self._target(*self._args, **self._kwargs)
  File "C:\Users\HP\Documents\Axsos_academy\Django\djangoPy3Env\lib\site-packages\django\utils\autoreload.py", line 54, in wrapper
    fn(*args, **kwargs)
  File "C:\Users\HP\Documents\Axsos_academy\Django\djangoPy3Env\lib\site-packages\django\core\management\commands\runserver.py", line 109, in inner_run
    autoreload.raise_last_exception()
  File "C:\Users\HP\Documents\Axsos_academy\Django\djangoPy3Env\lib\site-packages\django\utils\autoreload.py", line 77, in raise_last_exception
    raise _exception[1]
  File "C:\Users\HP\Documents\Axsos_academy\Django\djangoPy3Env\lib\site-packages\django\core\management\__init__.py", line 337, in execute
    autoreload.check_errors(django.setup)()
  File "C:\Users\HP\Documents\Axsos_academy\Django\djangoPy3Env\lib\site-packages\django\utils\autoreload.py", line 54, in wrapper
    fn(*args, **kwargs)
  File "C:\Users\HP\Documents\Axsos_academy\Django\djangoPy3Env\lib\site-packages\django\__init__.py", line 24, in setup
    apps.populate(settings.INSTALLED_APPS)
  File "C:\Users\HP\Documents\Axsos_academy\Django\djangoPy3Env\lib\site-packages\django\apps\registry.py", line 114, in populate
    app_config.import_models()
  File "C:\Users\HP\Documents\Axsos_academy\Django\djangoPy3Env\lib\site-packages\django\apps\config.py", line 211, in import_models
    self.models_module = import_module(models_module_name)
  File "C:\Users\HP\AppData\Local\Programs\Python\Python36-32\lib\importlib\__init__.py", line 126, in import_module
    return _bootstrap._gcd_import(name[level:], package, level)
  File "<frozen importlib._bootstrap>", line 994, in _gcd_import
  File "<frozen importlib._bootstrap>", line 971, in _find_and_load
  File "<frozen importlib._bootstrap>", line 955, in _find_and_load_unlocked
  File "<frozen importlib._bootstrap>", line 665, in _load_unlocked
  File "<frozen importlib._bootstrap_external>", line 678, in exec_module
  File "<frozen importlib._bootstrap>", line 219, in _call_with_frames_removed
  File "C:\Users\HP\Documents\Axsos_academy\Django\django_intro\Dojoservey\dojo_servey\models.py", line 9, in <module>
    class user(models.Model):
  File "C:\Users\HP\Documents\Axsos_academy\Django\django_intro\Dojoservey\dojo_servey\models.py", line 11, in user
    first_name= CharField(max_length=45)
NameError: name 'CharField' is not defined

C:\Users\HP\Documents\Axsos_academy\Django\django_intro\Dojoservey\dojo_servey\models.py changed, reloading.
Watching for file changes with StatReloader
Performing system checks...

System check identified no issues (0 silenced).

You have 17 unapplied migration(s). Your project may not work properly until you apply the migrations for app(s): admin, auth, contenttypes, sessions.
Run 'python manage.py migrate' to apply them.
September 22, 2022 - 10:53:39
Django version 2.2.4, using settings 'Dojoservey.settings'
Starting development server at http://127.0.0.1:8000/
Quit the server with CTRL-BREAK.
C:\Users\HP\Documents\Axsos_academy\Django\django_intro\Dojoservey\dojo_servey\models.py changed, reloading.
Watching for file changes with StatReloader
Performing system checks...

System check identified no issues (0 silenced).

You have 17 unapplied migration(s). Your project may not work properly until you apply the migrations for app(s): admin, auth, contenttypes, sessions.
Run 'python manage.py migrate' to apply them.
September 22, 2022 - 10:53:54
Django version 2.2.4, using settings 'Dojoservey.settings'
Starting development server at http://127.0.0.1:8000/
Quit the server with CTRL-BREAK.
C:\Users\HP\Documents\Axsos_academy\Django\django_intro\Dojoservey\dojo_servey\models.py changed, reloading.
Watching for file changes with StatReloader
Performing system checks...

System check identified no issues (0 silenced).

You have 17 unapplied migration(s). Your project may not work properly until you apply the migrations for app(s): admin, auth, contenttypes, sessions.
Run 'python manage.py migrate' to apply them.
September 22, 2022 - 10:53:59
Django version 2.2.4, using settings 'Dojoservey.settings'
Starting development server at http://127.0.0.1:8000/
Quit the server with CTRL-BREAK.
C:\Users\HP\Documents\Axsos_academy\Django\django_intro\Dojoservey\dojo_servey\models.py changed, reloading.
Watching for file changes with StatReloader
Exception in thread django-main-thread:
Traceback (most recent call last):
  File "C:\Users\HP\AppData\Local\Programs\Python\Python36-32\lib\threading.py", line 916, in _bootstrap_inner
    self.run()
  File "C:\Users\HP\AppData\Local\Programs\Python\Python36-32\lib\threading.py", line 864, in run
    self._target(*self._args, **self._kwargs)
  File "C:\Users\HP\Documents\Axsos_academy\Django\djangoPy3Env\lib\site-packages\django\utils\autoreload.py", line 54, in wrapper
    fn(*args, **kwargs)
  File "C:\Users\HP\Documents\Axsos_academy\Django\djangoPy3Env\lib\site-packages\django\core\management\commands\runserver.py", line 109, in inner_run
    autoreload.raise_last_exception()
  File "C:\Users\HP\Documents\Axsos_academy\Django\djangoPy3Env\lib\site-packages\django\utils\autoreload.py", line 77, in raise_last_exception
    raise _exception[1]
  File "C:\Users\HP\Documents\Axsos_academy\Django\djangoPy3Env\lib\site-packages\django\core\management\__init__.py", line 337, in execute
    autoreload.check_errors(django.setup)()
  File "C:\Users\HP\Documents\Axsos_academy\Django\djangoPy3Env\lib\site-packages\django\utils\autoreload.py", line 54, in wrapper
    fn(*args, **kwargs)
  File "C:\Users\HP\Documents\Axsos_academy\Django\djangoPy3Env\lib\site-packages\django\__init__.py", line 24, in setup
    apps.populate(settings.INSTALLED_APPS)
  File "C:\Users\HP\Documents\Axsos_academy\Django\djangoPy3Env\lib\site-packages\django\apps\registry.py", line 114, in populate
    app_config.import_models()
  File "C:\Users\HP\Documents\Axsos_academy\Django\djangoPy3Env\lib\site-packages\django\apps\config.py", line 211, in import_models
    self.models_module = import_module(models_module_name)
  File "C:\Users\HP\AppData\Local\Programs\Python\Python36-32\lib\importlib\__init__.py", line 126, in import_module
    return _bootstrap._gcd_import(name[level:], package, level)
  File "<frozen importlib._bootstrap>", line 994, in _gcd_import
  File "<frozen importlib._bootstrap>", line 971, in _find_and_load
  File "<frozen importlib._bootstrap>", line 955, in _find_and_load_unlocked
  File "<frozen importlib._bootstrap>", line 665, in _load_unlocked
  File "<frozen importlib._bootstrap_external>", line 674, in exec_module
  File "<frozen importlib._bootstrap_external>", line 781, in get_code
  File "<frozen importlib._bootstrap_external>", line 741, in source_to_code
  File "<frozen importlib._bootstrap>", line 219, in _call_with_frames_removed
  File "C:\Users\HP\Documents\Axsos_academy\Django\django_intro\Dojoservey\dojo_servey\models.py", line 14
    age = models.in
                  ^
SyntaxError: invalid syntax

C:\Users\HP\Documents\Axsos_academy\Django\django_intro\Dojoservey\dojo_servey\models.py changed, reloading.
Watching for file changes with StatReloader
Exception in thread django-main-thread:
Traceback (most recent call last):
  File "C:\Users\HP\AppData\Local\Programs\Python\Python36-32\lib\threading.py", line 916, in _bootstrap_inner
    self.run()
  File "C:\Users\HP\AppData\Local\Programs\Python\Python36-32\lib\threading.py", line 864, in run
    self._target(*self._args, **self._kwargs)
  File "C:\Users\HP\Documents\Axsos_academy\Django\djangoPy3Env\lib\site-packages\django\utils\autoreload.py", line 54, in wrapper
    fn(*args, **kwargs)
  File "C:\Users\HP\Documents\Axsos_academy\Django\djangoPy3Env\lib\site-packages\django\core\management\commands\runserver.py", line 109, in inner_run
    autoreload.raise_last_exception()
  File "C:\Users\HP\Documents\Axsos_academy\Django\djangoPy3Env\lib\site-packages\django\utils\autoreload.py", line 77, in raise_last_exception
    raise _exception[1]
  File "C:\Users\HP\Documents\Axsos_academy\Django\djangoPy3Env\lib\site-packages\django\core\management\__init__.py", line 337, in execute
    autoreload.check_errors(django.setup)()
  File "C:\Users\HP\Documents\Axsos_academy\Django\djangoPy3Env\lib\site-packages\django\utils\autoreload.py", line 54, in wrapper
    fn(*args, **kwargs)
  File "C:\Users\HP\Documents\Axsos_academy\Django\djangoPy3Env\lib\site-packages\django\__init__.py", line 24, in setup
    apps.populate(settings.INSTALLED_APPS)
  File "C:\Users\HP\Documents\Axsos_academy\Django\djangoPy3Env\lib\site-packages\django\apps\registry.py", line 114, in populate
    app_config.import_models()
  File "C:\Users\HP\Documents\Axsos_academy\Django\djangoPy3Env\lib\site-packages\django\apps\config.py", line 211, in import_models
    self.models_module = import_module(models_module_name)
  File "C:\Users\HP\AppData\Local\Programs\Python\Python36-32\lib\importlib\__init__.py", line 126, in import_module
    return _bootstrap._gcd_import(name[level:], package, level)
  File "<frozen importlib._bootstrap>", line 994, in _gcd_import
  File "<frozen importlib._bootstrap>", line 971, in _find_and_load
  File "<frozen importlib._bootstrap>", line 955, in _find_and_load_unlocked
  File "<frozen importlib._bootstrap>", line 665, in _load_unlocked
  File "<frozen importlib._bootstrap_external>", line 678, in exec_module
  File "<frozen importlib._bootstrap>", line 219, in _call_with_frames_removed
  File "C:\Users\HP\Documents\Axsos_academy\Django\django_intro\Dojoservey\dojo_servey\models.py", line 9, in <module>
    class user(models.Model):
  File "C:\Users\HP\Documents\Axsos_academy\Django\django_intro\Dojoservey\dojo_servey\models.py", line 14, in user
    age = models.I
AttributeError: module 'django.db.models' has no attribute 'I'

C:\Users\HP\Documents\Axsos_academy\Django\django_intro\Dojoservey\dojo_servey\models.py changed, reloading.
Watching for file changes with StatReloader
Performing system checks...

System check identified no issues (0 silenced).

You have 17 unapplied migration(s). Your project may not work properly until you apply the migrations for app(s): admin, auth, contenttypes, sessions.
Run 'python manage.py migrate' to apply them.
September 22, 2022 - 10:54:09
Django version 2.2.4, using settings 'Dojoservey.settings'
Starting development server at http://127.0.0.1:8000/
Quit the server with CTRL-BREAK.
C:\Users\HP\Documents\Axsos_academy\Django\django_intro\Dojoservey\dojo_servey\models.py changed, reloading.
Watching for file changes with StatReloader
Performing system checks...

Exception in thread django-main-thread:
Traceback (most recent call last):
  File "C:\Users\HP\AppData\Local\Programs\Python\Python36-32\lib\threading.py", line 916, in _bootstrap_inner
    self.run()
  File "C:\Users\HP\AppData\Local\Programs\Python\Python36-32\lib\threading.py", line 864, in run
    self._target(*self._args, **self._kwargs)
  File "C:\Users\HP\Documents\Axsos_academy\Django\djangoPy3Env\lib\site-packages\django\utils\autoreload.py", line 54, in wrapper
    fn(*args, **kwargs)
  File "C:\Users\HP\Documents\Axsos_academy\Django\djangoPy3Env\lib\site-packages\django\core\management\commands\runserver.py", line 117, in inner_run
    self.check(display_num_errors=True)
  File "C:\Users\HP\Documents\Axsos_academy\Django\djangoPy3Env\lib\site-packages\django\core\management\base.py", line 436, in check
    raise SystemCheckError(msg)
django.core.management.base.SystemCheckError: SystemCheckError: System check identified some issues:

ERRORS:
dojo_servey.user.age: (fields.E210) Cannot use ImageField because Pillow is not installed.
        HINT: Get Pillow at https://pypi.org/project/Pillow/ or run command "pip install Pillow".

System check identified 1 issue (0 silenced).

C:\Users\HP\Documents\Axsos_academy\Django\django_intro\Dojoservey\dojo_servey\models.py changed, reloading.
Watching for file changes with StatReloader
Performing system checks...

Exception in thread django-main-thread:
Traceback (most recent call last):
  File "C:\Users\HP\AppData\Local\Programs\Python\Python36-32\lib\threading.py", line 916, in _bootstrap_inner
    self.run()
  File "C:\Users\HP\AppData\Local\Programs\Python\Python36-32\lib\threading.py", line 864, in run
    self._target(*self._args, **self._kwargs)
  File "C:\Users\HP\Documents\Axsos_academy\Django\djangoPy3Env\lib\site-packages\django\utils\autoreload.py", line 54, in wrapper
    fn(*args, **kwargs)
  File "C:\Users\HP\Documents\Axsos_academy\Django\djangoPy3Env\lib\site-packages\django\core\management\commands\runserver.py", line 117, in inner_run
    self.check(display_num_errors=True)
  File "C:\Users\HP\Documents\Axsos_academy\Django\djangoPy3Env\lib\site-packages\django\core\management\base.py", line 436, in check
    raise SystemCheckError(msg)
django.core.management.base.SystemCheckError: SystemCheckError: System check identified some issues:

ERRORS:
dojo_servey.User.age: (fields.E210) Cannot use ImageField because Pillow is not installed.
        HINT: Get Pillow at https://pypi.org/project/Pillow/ or run command "pip install Pillow".

System check identified 1 issue (0 silenced).


(djangoPy3Env) C:\Users\HP\Documents\Axsos_academy\Django\django_intro\Dojoservey>python manage.py sell
Unknown command: 'sell'. Did you mean shell?
Type 'manage.py help' for usage.

(djangoPy3Env) C:\Users\HP\Documents\Axsos_academy\Django\django_intro\Dojoservey>> python manage.py shell

(djangoPy3Env) C:\Users\HP\Documents\Axsos_academy\Django\django_intro\Dojoservey>
(djangoPy3Env) C:\Users\HP\Documents\Axsos_academy\Django\django_intro\Dojoservey>
> python manage.py shellexit()

(djangoPy3Env) C:\Users\HP\Documents\Axsos_academy\Django\django_intro\Dojoservey>


(djangoPy3Env) C:\Users\HP\Documents\Axsos_academy\Django\django_intro\Dojoservey>> python manage.py makemigrations

(djangoPy3Env) C:\Users\HP\Documents\Axsos_academy\Django\django_intro\Dojoservey>
quiet()
'quiet' is not recognized as an internal or external command,
operable program or batch file.

(djangoPy3Env) C:\Users\HP\Documents\Axsos_academy\Django\django_intro\Dojoservey>python manage.py makemigrations
SystemCheckError: System check identified some issues:

ERRORS:
dojo_servey.User.age: (fields.E210) Cannot use ImageField because Pillow is not installed.
        HINT: Get Pillow at https://pypi.org/project/Pillow/ or run command "pip install Pillow".

(djangoPy3Env) C:\Users\HP\Documents\Axsos_academy\Django\django_intro\Dojoservey>python manage.py makemigrations
Migrations for 'dojo_servey':
  dojo_servey\migrations\0001_initial.py
    - Create model User

(djangoPy3Env) C:\Users\HP\Documents\Axsos_academy\Django\django_intro\Dojoservey>python manage.py migration
Unknown command: 'migration'. Did you mean showmigrations?
Type 'manage.py help' for usage.

(djangoPy3Env) C:\Users\HP\Documents\Axsos_academy\Django\django_intro\Dojoservey>python manage.py migrate
Operations to perform:
  Apply all migrations: admin, auth, contenttypes, dojo_servey, sessions
Running migrations:
  Applying contenttypes.0001_initial... OK
  Applying auth.0001_initial... OK
  Applying admin.0001_initial... OK
  Applying admin.0002_logentry_remove_auto_add... OK
  Applying admin.0003_logentry_add_action_flag_choices... OK
  Applying contenttypes.0002_remove_content_type_name... OK
  Applying auth.0002_alter_permission_name_max_length... OK
  Applying auth.0003_alter_user_email_max_length... OK
  Applying auth.0004_alter_user_username_opts... OK
  Applying auth.0005_alter_user_last_login_null... OK
  Applying auth.0006_require_contenttypes_0002... OK
  Applying auth.0007_alter_validators_add_error_messages... OK
  Applying auth.0008_alter_user_username_max_length... OK
  Applying auth.0009_alter_user_last_name_max_length... OK
  Applying auth.0010_alter_group_name_max_length... OK
  Applying auth.0011_update_proxy_permissions... OK
  Applying dojo_servey.0001_initial... OK
  Applying sessions.0001_initial... OK

(djangoPy3Env) C:\Users\HP\Documents\Axsos_academy\Django\django_intro\Dojoservey>python manage.py sell
Unknown command: 'sell'. Did you mean shell?
Type 'manage.py help' for usage.

(djangoPy3Env) C:\Users\HP\Documents\Axsos_academy\Django\django_intro\Dojoservey>python manage.py shell
Python 3.6.4 (v3.6.4:d48eceb, Dec 19 2017, 06:04:45) [MSC v.1900 32 bit (Intel)] on win32
Type "help", "copyright", "credits" or "license" for more information.
(InteractiveConsole)
>>> from dojo_servey.models import *
>>> User.opject.creat(first_name="yusef",last_name="asd",age=23,email="asdfaf@zscz")
Traceback (most recent call last):
  File "<console>", line 1, in <module>
AttributeError: type object 'User' has no attribute 'opject'
>>> User.opject.creat(first_name="yusef",last_name="asd",email="asdsasd@asdasd",age=23")
  File "<console>", line 1
    User.opject.creat(first_name="yusef",last_name="asd",email="asdsasd@asdasd",age=23")
                                                                                       ^
SyntaxError: EOL while scanning string literal
>>> User.opject.creat(first_name="laith",last_name="asd",email="asdsasd@asdasd",age=53")
  File "<console>", line 1
    User.opject.creat(first_name="laith",last_name="asd",email="asdsasd@asdasd",age=53")
                                                                                       ^
SyntaxError: EOL while scanning string literal
>>> User.opject.creat(first_name="laith",last_name="asd",email="asdsasd@asdasd",age=53)
Traceback (most recent call last):
  File "<console>", line 1, in <module>
AttributeError: type object 'User' has no attribute 'opject'
>>> User.objects.create(first_name="laith",last_name="asd",email="asdsasd@asdasd",age=53)
<User: User object (1)>
>>> User.objects.create(first_name="yoouseef",last_name="asd",email="asdsasd@asdasd",age=42)
<User: User object (2)>
>>> User.objects.create(first_name=rami",last_name="dddd",email="asdsasd@asdasd",age=82)
  File "<console>", line 1
    User.objects.create(first_name=rami",last_name="dddd",email="asdsasd@asdasd",age=82)
                                                   ^
SyntaxError: invalid syntax
>>> User.objects.create(first_name="rami",last_name="dddd",email="asdsasd@asdasd",age=82)
<User: User object (3)>
>>> User.objects.all().values()
<QuerySet [{'id': 1, 'title': '', 'first_name': 'laith', 'last_name': 'asd', 'email': 'asdsasd@asdasd', 'age': 53, 'created_at': datetime.datetime(2022, 9, 22, 8, 6, 42, 88515, tzinfo=<UTC>), 'updated_at': datetime.datetime(2022, 9, 22, 8, 6, 42, 88515, tzinfo=<UTC>)}, {'id': 2, 'title': '', 'first_name': 'yoouseef', 'last_name': 'asd', 'email': 'asdsasd@asdasd', 'age': 42, 'created_at': datetime.datetime(2022, 9, 22, 8, 7, 11, 925184, tzinfo=<UTC>), 'updated_at': datetime.datetime(2022, 9, 22, 8, 7, 11, 925184, tzinfo=<UTC>)}, {'id': 3, 'title': '', 'first_name': 'rami', 'last_name': 'dddd', 'email': 'asdsasd@asdasd', 'age': 82, 'created_at': datetime.datetime(2022, 9, 22, 8, 8, 5, 347189, tzinfo=<UTC>), 'updated_at': datetime.datetime(2022, 9, 22, 8, 8, 5, 347189, tzinfo=<UTC>)}]>
>>> User.objects.last().__dict__
{'_state': <django.db.models.base.ModelState object at 0x00D15890>, 'id': 3, 'title': '', 'first_name': 'rami', 'last_name': 'dddd', 'email': 'asdsasd@asdasd', 'age': 82, 'created_at': datetime.datetime(2022, 9, 22, 8, 8, 5, 347189, tzinfo=<UTC>), 'updated_at': datetime.datetime(2022, 9, 22, 8, 8, 5, 347189, tzinfo=<UTC>)}
>>> User.objects.first().__dict__
{'_state': <django.db.models.base.ModelState object at 0x00D15910>, 'id': 1, 'title': '', 'first_name': 'laith', 'last_name': 'asd', 'email': 'asdsasd@asdasd', 'age': 53, 'created_at': datetime.datetime(2022, 9, 22, 8, 6, 42, 88515, tzinfo=<UTC>), 'updated_at': datetime.datetime(2022, 9, 22, 8, 6, 42, 88515, tzinfo=<UTC>)}
>>> c=User.objects.get(id=3)
>>> c.first_name
'rami'
>>> c.first_name="ahmad"
>>> c.save
<bound method Model.save of <User: User object (3)>>
>>> User.objects.first().__dict__
{'_state': <django.db.models.base.ModelState object at 0x00D15A70>, 'id': 1, 'title': '', 'first_name': 'laith', 'last_name': 'asd', 'email': 'asdsasd@asdasd', 'age': 53, 'created_at': datetime.datetime(2022, 9, 22, 8, 6, 42, 88515, tzinfo=<UTC>), 'updated_at': datetime.datetime(2022, 9, 22, 8, 6, 42, 88515, tzinfo=<UTC>)}
>>> User.objects.all().__dict__
{'model': <class 'dojo_servey.models.User'>, '_db': None, '_hints': {}, 'query': <django.db.models.sql.query.Query object at 0x03B7F0B0>, '_result_cache': None, '_sticky_filter': False, '_for_write': False, '_prefetch_related_lookups': (), '_prefetch_done': False, '_known_related_objects': {}, '_iterable_class': <class 'django.db.models.query.ModelIterable'>, '_fields': None}
>>> User.objects.all().values()
<QuerySet [{'id': 1, 'title': '', 'first_name': 'laith', 'last_name': 'asd', 'email': 'asdsasd@asdasd', 'age': 53, 'created_at': datetime.datetime(2022, 9, 22, 8, 6, 42, 88515, tzinfo=<UTC>), 'updated_at': datetime.datetime(2022, 9, 22, 8, 6, 42, 88515, tzinfo=<UTC>)}, {'id': 2, 'title': '', 'first_name': 'yoouseef', 'last_name': 'asd', 'email': 'asdsasd@asdasd', 'age': 42, 'created_at': datetime.datetime(2022, 9, 22, 8, 7, 11, 925184, tzinfo=<UTC>), 'updated_at': datetime.datetime(2022, 9, 22, 8, 7, 11, 925184, tzinfo=<UTC>)}, {'id': 3, 'title': '', 'first_name': 'rami', 'last_name': 'dddd', 'email': 'asdsasd@asdasd', 'age': 82, 'created_at': datetime.datetime(2022, 9, 22, 8, 8, 5, 347189, tzinfo=<UTC>), 'updated_at': datetime.datetime(2022, 9, 22, 8, 8, 5, 347189, tzinfo=<UTC>)}]>
>>> c.save()
>>> User.objects.all().values()
<QuerySet [{'id': 1, 'title': '', 'first_name': 'laith', 'last_name': 'asd', 'email': 'asdsasd@asdasd', 'age': 53, 'created_at': datetime.datetime(2022, 9, 22, 8, 6, 42, 88515, tzinfo=<UTC>), 'updated_at': datetime.datetime(2022, 9, 22, 8, 6, 42, 88515, tzinfo=<UTC>)}, {'id': 2, 'title': '', 'first_name': 'yoouseef', 'last_name': 'asd', 'email': 'asdsasd@asdasd', 'age': 42, 'created_at': datetime.datetime(2022, 9, 22, 8, 7, 11, 925184, tzinfo=<UTC>), 'updated_at': datetime.datetime(2022, 9, 22, 8, 7, 11, 925184, tzinfo=<UTC>)}, {'id': 3, 'title': '', 'first_name': 'ahmad', 'last_name': 'dddd', 'email': 'asdsasd@asdasd', 'age': 82, 'created_at': datetime.datetime(2022, 9, 22, 8, 8, 5, 347189, tzinfo=<UTC>), 'updated_at': datetime.datetime(2022, 9, 22, 8, 27, 32, 296602, tzinfo=<UTC>)}]>
>>> d=User.objects.get(id=3)
>>> d.delete()
(1, {'dojo_servey.User': 1})
>>> User.objects.all().values()
<QuerySet [{'id': 1, 'title': '', 'first_name': 'laith', 'last_name': 'asd', 'email': 'asdsasd@asdasd', 'age': 53, 'created_at': datetime.datetime(2022, 9, 22, 8, 6, 42, 88515, tzinfo=<UTC>), 'updated_at': datetime.datetime(2022, 9, 22, 8, 6, 42, 88515, tzinfo=<UTC>)}, {'id': 2, 'title': '', 'first_name': 'yoouseef', 'last_name': 'asd', 'email': 'asdsasd@asdasd', 'age': 42, 'created_at': datetime.datetime(2022, 9, 22, 8, 7, 11, 925184, tzinfo=<UTC>), 'updated_at': datetime.datetime(2022, 9, 22, 8, 7, 11, 925184, tzinfo=<UTC>)}]>
>>> User.objects.all().order_by("first_name").values
<bound method QuerySet.values of <QuerySet [<User: User object (1)>, <User: User object (2)>]>>
>>> User.objects.all().order_by("first_name").values()
<QuerySet [{'id': 1, 'title': '', 'first_name': 'laith', 'last_name': 'asd', 'email': 'asdsasd@asdasd', 'age': 53, 'created_at': datetime.datetime(2022, 9, 22, 8, 6, 42, 88515, tzinfo=<UTC>), 'updated_at': datetime.datetime(2022, 9, 22, 8, 6, 42, 88515, tzinfo=<UTC>)}, {'id': 2, 'title': '', 'first_name': 'yoouseef', 'last_name': 'asd', 'email': 'asdsasd@asdasd', 'age': 42, 'created_at': datetime.datetime(2022, 9, 22, 8, 7, 11, 925184, tzinfo=<UTC>), 'updated_at': datetime.datetime(2022, 9, 22, 8, 7, 11, 925184, tzinfo=<UTC>)}]>
>>> User.objects.all().order_by("-first_name").values()
<QuerySet [{'id': 2, 'title': '', 'first_name': 'yoouseef', 'last_name': 'asd', 'email': 'asdsasd@asdasd', 'age': 42, 'created_at': datetime.datetime(2022, 9, 22, 8, 7, 11, 925184, tzinfo=<UTC>), 'updated_at': datetime.datetime(2022, 9, 22, 8, 7, 11, 925184, tzinfo=<UTC>)}, {'id': 1, 'title': '', 'first_name': 'laith', 'last_name': 'asd', 'email': 'asdsasd@asdasd', 'age': 53, 'created_at': datetime.datetime(2022, 9, 22, 8, 6, 42, 88515, tzinfo=<UTC>), 'updated_at': datetime.datetime(2022, 9, 22, 8, 6, 42, 88515, tzinfo=<UTC>)}]>
>>>